Workbook

Sheet Rainfall Data
A1: Site Reference Number | B1: SN25
A2: Site Name | B2: Fadugu Agricultural College
A3: Latitude | B3: 9.4029
A4: Longitude | B4: -11.77276
A5: Elevation (mASL) | B5: 302 | C5: m above sea level
A6: Type of Data | B6: Rainfall Data
A7: Data Collection | B7: Community (School)
A8: Origin | B8: Sierra Leone Ministry of Water Resources, Water Supply Division
A9: Ownership | B9: Sierra Leone Ministry of Water Resources
A10: Other Details | B10: Water Security Project, 2012 to 2015
A11: Web Site | B11: www.salonewatersecurity.com
A12: Start of Data Record | B12: =+MIN(A:A)-1 -> 41759.375
A13: End of Data Record | B13: =+MAX(A:A)-1 -> 42642.375
A14: Number of Data Records | B14: =+COUNT(A:A) -> 884
A15: Data Notes | B15: nd = no data; T = Trace (<0.5mm)
A17: Date of Measurement (at 9am) | B17: Official Record Date (Preceding Day) | C17: Daily Rainfall
C18: mm
A19: 41760.375 | B19: 41759 | C19: 0
A20: 41761.375 | B20: 41760 | C20: 0
A21: 41762.375 | B21: 41761 | C21: 0
A22: 41763.375 | B22: 41762 | C22: 0
A23: 41764.375 | B23: 41763 | C23: 0
A24: 41765.375 | B24: 41764 | C24: 0
A25: 41766.375 | B25: 41765 | C25: 0
A26: 41767.375 | B26: 41766 | C26: 0
A27: 41768.375 | B27: 41767 | C27: 0
A28: 41769.375 | B28: 41768 | C28: 0
A29: 41770.375 | B29: 41769 | C29: 0
A30: 41771.375 | B30: 41770 | C30: 0
... A49: 41790.375 | B49: 41789 | C49: 1
A50: 41791.375 | B50: 41790 | C50: T
A51: 41792.375 | B51: 41791 | C51: 0
A52: 41793.375 | B52: 41792 | C52: 0
A53: 41794.375 | B53: 41793 | C53: 46
A54: 41795.375 | B54: 41794 | C54: 21
A55: 41796.375 | B55: 41795 | C55: 31
A56: 41797.375 | B56: 41796 | C56: 29
A57: 41798.375 | B57: 41797 | C57: 0
A58: 41799.375 | B58: 41798 | C58: 0
A59: 41800.375 | B59: 41799 | C59: 0
...

Sheet Rainfall Totals
A1: Site Reference Number | B1: =+'Rainfall Data'!B1 -> SN25
A2: Site Name | B2: =+'Rainfall Data'!B2 -> Fadugu Agricultural College
A3: Latitude | B3: =+'Rainfall Data'!B3 -> 9.4029
A4: Longitude | B4: =+'Rainfall Data'!B4 -> -11.77276
A5: Elevation (mASL) | B5: =+'Rainfall Data'!B5 -> 302 | C5: =+'Rainfall Data'!C5 -> m above sea level
A6: Type of Data | B6: =+'Rainfall Data'!B6 -> Rainfall Data
A7: Data Collection | B7: =+'Rainfall Data'!B7 -> Community (School)
A8: Origin | B8: =+'Rainfall Data'!B8 -> Sierra Leone Ministry of Water Resources, Water Supply Division
A9: Ownership | B9: =+'Rainfall Data'!B9 -> Sierra Leone Ministry of Water Resources
A10: Other Details | B10: =+'Rainfall Data'!B10 -> Water Security Project, 2012 to 2015
A11: Web Site | B11: =+'Rainfall Data'!B11 -> www.salonewatersecurity.com
A12: Start of Data Record | B12: =+MIN(A:A) -> 41759
A13: End of Data Record | B13: =+MAX(A:A) -> 42642
A14: Number of Data Records | B14: =+COUNT(A:A) -> 884
A15: Data Notes | B15: =+'Rainfall Data'!B15 -> nd = no data; T = Trace (<0.5mm)
A17: Daily and Cumulative Rainfall (mm) | F17: Monthly Rainfall (mm) | M17: Annual Rainfall (mm)
A18: Official Record Date (Preceding Day) | B18: Daily Rainfall | C18: Cumulative Rainfall | D18: Year/Month | F18: Month | G18: Monthly Rainfall | H18: Cumulative | I18: Year | J18: Year/Month | K18: Incomplete Data | M18: Year | N18: Annual Rainfall | O18: Incomplete Data | P18: Notes
B19: mm | C19: mm | G19: mm | H19: mm | N19: mm
A20: =+'Rainfall Data'!B19 -> 41759 | B20: =+'Rainfall Data'!C19 -> 0 | C20: =IF(B20="nd",0, IF(B20="T",0,B20)) -> 0 | D20: =+YEAR(A20)*1000+MONTH(A20) -> 2014004 | F20: 41640 | I20: =+YEAR(F20) -> 2014 | J20: =+YEAR(F20)*1000+MONTH(F20) -> 2014001 | M20: 2014 | N20: =SUMIF($I$20:$I$111,M20,$G$20:$G$111) -> 1732.1 | O20: * | P20: May onwards
A21: =+'Rainfall Data'!B20 -> 41760 | B21: =+'Rainfall Data'!C20 -> 0 | C21: =IF(B21="nd",0, IF(B21="T",0,B21))+C20 -> 0 | D21: =+YEAR(A21)*1000+MONTH(A21) -> 2014005 | F21: 41671 | I21: =+YEAR(F21) -> 2014 | J21: =+YEAR(F21)*1000+MONTH(F21) -> 2014002 | M21: 2015 | N21: =SUMIF($I$20:$I$111,M21,$G$20:$G$111) -> 1884 | O21: * | P21: nd: Jul, Dec
A22: =+'Rainfall Data'!B21 -> 41761 | B22: =+'Rainfall Data'!C21 -> 0 | C22: =IF(B22="nd",0, IF(B22="T",0,B22))+C21 -> 0 | D22: =+YEAR(A22)*1000+MONTH(A22) -> 2014005 | F22: 41699 | I22: =+YEAR(F22) -> 2014 | J22: =+YEAR(F22)*1000+MONTH(F22) -> 2014003 | M22: 2016 | N22: =SUMIF($I$20:$I$111,M22,$G$20:$G$111) -> 1121.4 | O22: * | P22: nd: Feb, Mar, Apr
A23: =+'Rainfall Data'!B22 -> 41762 | B23: =+'Rainfall Data'!C22 -> 0 | C23: =IF(B23="nd",0, IF(B23="T",0,B23))+C22 -> 0 | D23: =+YEAR(A23)*1000+MONTH(A23) -> 2014005 | F23: 41730 | I23: =+YEAR(F23) -> 2014 | J23: =+YEAR(F23)*1000+MONTH(F23) -> 2014004
A24: =+'Rainfall Data'!B23 -> 41763 | B24: =+'Rainfall Data'!C23 -> 0 | C24: =IF(B24="nd",0, IF(B24="T",0,B24))+C23 -> 0 | D24: =+YEAR(A24)*1000+MONTH(A24) -> 2014005 | F24: 41760 | G24: =SUMIF($D$20:$D$10011,J24,$B$20:$B$10011) -> 123.6 | H24: =IF(G24="nd",0, IF(G24="T",0,G24))+H23 -> 123.6 | I24: =+YEAR(F24) -> 2014 | J24: =+YEAR(F24)*1000+MONTH(F24) -> 2014005
A25: =+'Rainfall Data'!B24 -> 41764 | B25: =+'Rainfall Data'!C24 -> 0 | C25: =IF(B25="nd",0, IF(B25="T",0,B25))+C24 -> 0 | D25: =+YEAR(A25)*1000+MONTH(A25) -> 2014005 | F25: 41791 | G25: =SUMIF($D$20:$D$10011,J25,$B$20:$B$10011) -> 303 | H25: =IF(G25="nd",0, IF(G25="T",0,G25))+H24 -> 426.6 | I25: =+YEAR(F25) -> 2014 | J25: =+YEAR(F25)*1000+MONTH(F25) -> 2014006
A26: =+'Rainfall Data'!B25 -> 41765 | B26: =+'Rainfall Data'!C25 -> 0 | C26: =IF(B26="nd",0, IF(B26="T",0,B26))+C25 -> 0 | D26: =+YEAR(A26)*1000+MONTH(A26) -> 2014005 | F26: 41821 | G26: =SUMIF($D$20:$D$10011,J26,$B$20:$B$10011) -> 305 | H26: =IF(G26="nd",0, IF(G26="T",0,G26))+H25 -> 731.6 | I26: =+YEAR(F26) -> 2014 | J26: =+YEAR(F26)*1000+MONTH(F26) -> 2014007
A27: =+'Rainfall Data'!B26 -> 41766 | B27: =+'Rainfall Data'!C26 -> 0 | C27: =IF(B27="nd",0, IF(B27="T",0,B27))+C26 -> 0 | D27: =+YEAR(A27)*1000+MONTH(A27) -> 2014005 | F27: 41852 | G27: =SUMIF($D$20:$D$10011,J27,$B$20:$B$10011) -> 411.5 | H27: =IF(G27="nd",0, IF(G27="T",0,G27))+H26 -> 1143.1 | I27: =+YEAR(F27) -> 2014 | J27: =+YEAR(F27)*1000+MONTH(F27) -> 2014008
A28: =+'Rainfall Data'!B27 -> 41767 | B28: =+'Rainfall Data'!C27 -> 0 | C28: =IF(B28="nd",0, IF(B28="T",0,B28))+C27 -> 0 | D28: =+YEAR(A28)*1000+MONTH(A28) -> 2014005 | F28: 41883 | G28: =SUMIF($D$20:$D$10011,J28,$B$20:$B$10011) -> 298 | H28: =IF(G28="nd",0, IF(G28="T",0,G28))+H27 -> 1441.1 | I28: =+YEAR(F28) -> 2014 | J28: =+YEAR(F28)*1000+MONTH(F28) -> 2014009
A29: =+'Rainfall Data'!B28 -> 41768 | B29: =+'Rainfall Data'!C28 -> 0 | C29: =IF(B29="nd",0, IF(B29="T",0,B29))+C28 -> 0 | D29: =+YEAR(A29)*1000+MONTH(A29) -> 2014005 | F29: 41913 | G29: =SUMIF($D$20:$D$10011,J29,$B$20:$B$10011) -> 217 | H29: =IF(G29="nd",0, IF(G29="T",0,G29))+H28 -> 1658.1 | I29: =+YEAR(F29) -> 2014 | J29: =+YEAR(F29)*1000+MONTH(F29) -> 2014010
A30: =+'Rainfall Data'!B29 -> 41769 | B30: =+'Rainfall Data'!C29 -> 0 | C30: =IF(B30="nd",0, IF(B30="T",0,B30))+C29 -> 0 | D30: =+YEAR(A30)*1000+MONTH(A30) -> 2014005 | F30: 41944 | G30: =SUMIF($D$20:$D$10011,J30,$B$20:$B$10011) -> 74 | H30: =IF(G30="nd",0, IF(G30="T",0,G30))+H29 -> 1732.1 | I30: =+YEAR(F30) -> 2014 | J30: =+YEAR(F30)*1000+MONTH(F30) -> 2014011
A31: =+'Rainfall Data'!B30 -> 41770 | B31: =+'Rainfall Data'!C30 -> 0 | C31: =IF(B31="nd",0, IF(B31="T",0,B31))+C30 -> 0 | D31: =+YEAR(A31)*1000+MONTH(A31) -> 2014005 | F31: 41974 | G31: =SUMIF($D$20:$D$10011,J31,$B$20:$B$10011) -> 0 | H31: =IF(G31="nd",0, IF(G31="T",0,G31))+H30 -> 1732.1 | I31: =+YEAR(F31) -> 2014 | J31: =+YEAR(F31)*1000+MONTH(F31) -> 2014012
A32: =+'Rainfall Data'!B31 -> 41771 | B32: =+'Rainfall Data'!C31 -> 0 | C32: =IF(B32="nd",0, IF(B32="T",0,B32))+C31 -> 0 | D32: =+YEAR(A32)*1000+MONTH(A32) -> 2014005 | F32: 42005 | G32: =SUMIF($D$20:$D$10011,J32,$B$20:$B$10011) -> 0 | H32: =IF(G32="nd",0, IF(G32="T",0,G32)) -> 0 | I32: =+YEAR(F32) -> 2015 | J32: =+YEAR(F32)*1000+MONTH(F32) -> 2015001
A33: =+'Rainfall Data'!B32 -> 41772 | B33: =+'Rainfall Data'!C32 -> 0 | C33: =IF(B33="nd",0, IF(B33="T",0,B33))+C32 -> 0 | D33: =+YEAR(A33)*1000+MONTH(A33) -> 2014005 | F33: 42036 | G33: =SUMIF($D$20:$D$10011,J33,$B$20:$B$10011) -> 0 | H33: =IF(G33="nd",0, IF(G33="T",0,G33))+H32 -> 0 | I33: =+YEAR(F33) -> 2015 | J33: =+YEAR(F33)*1000+MONTH(F33) -> 2015002
A34: =+'Rainfall Data'!B33 -> 41773 | B34: =+'Rainfall Data'!C33 -> 0 | C34: =IF(B34="nd",0, IF(B34="T",0,B34))+C33 -> 0 | D34: =+YEAR(A34)*1000+MONTH(A34) -> 2014005 | F34: 42064 | G34: =SUMIF($D$20:$D$10011,J34,$B$20:$B$10011) -> 8.5 | H34: =IF(G34="nd",0, IF(G34="T",0,G34))+H33 -> 8.5 | I34: =+YEAR(F34) -> 2015 | J34: =+YEAR(F34)*1000+MONTH(F34) -> 2015003
A35: =+'Rainfall Data'!B34 -> 41774 | B35: =+'Rainfall Data'!C34 -> 0 | C35: =IF(B35="nd",0, IF(B35="T",0,B35))+C34 -> 0 | D35: =+YEAR(A35)*1000+MONTH(A35) -> 2014005 | F35: 42095 | G35: =SUMIF($D$20:$D$10011,J35,$B$20:$B$10011) -> 33.9 | H35: =IF(G35="nd",0, IF(G35="T",0,G35))+H34 -> 42.4 | I35: =+YEAR(F35) -> 2015 | J35: =+YEAR(F35)*1000+MONTH(F35) -> 2015004
A36: =+'Rainfall Data'!B35 -> 41775 | B36: =+'Rainfall Data'!C35 -> 25 | C36: =IF(B36="nd",0, IF(B36="T",0,B36))+C35 -> 25 | D36: =+YEAR(A36)*1000+MONTH(A36) -> 2014005 | F36: 42125 | G36: =SUMIF($D$20:$D$10011,J36,$B$20:$B$10011) -> 234.7 | H36: =IF(G36="nd",0, IF(G36="T",0,G36))+H35 -> 277.1 | I36: =+YEAR(F36) -> 2015 | J36: =+YEAR(F36)*1000+MONTH(F36) -> 2015005
A37: =+'Rainfall Data'!B36 -> 41776 | B37: =+'Rainfall Data'!C36 -> 31.5 | C37: =IF(B37="nd",0, IF(B37="T",0,B37))+C36 -> 56.5 | D37: =+YEAR(A37)*1000+MONTH(A37) -> 2014005 | F37: 42156 | G37: =SUMIF($D$20:$D$10011,J37,$B$20:$B$10011) -> 305.9 | H37: =IF(G37="nd",0, IF(G37="T",0,G37))+H36 -> 583 | I37: =+YEAR(F37) -> 2015 | J37: =+YEAR(F37)*1000+MONTH(F37) -> 2015006
A38: =+'Rainfall Data'!B37 -> 41777 | B38: =+'Rainfall Data'!C37 -> 0 | C38: =IF(B38="nd",0, IF(B38="T",0,B38))+C37 -> 56.5 | D38: =+YEAR(A38)*1000+MONTH(A38) -> 2014005 | F38: 42186 | G38: =SUMIF($D$20:$D$10011,J38,$B$20:$B$10011) -> 4.5 | H38: =IF(G38="nd",0, IF(G38="T",0,G38))+H37 -> 587.5 | I38: =+YEAR(F38) -> 2015 | J38: =+YEAR(F38)*1000+MONTH(F38) -> 2015007 | K38: *
A39: =+'Rainfall Data'!B38 -> 41778 | B39: =+'Rainfall Data'!C38 -> 0 | C39: =IF(B39="nd",0, IF(B39="T",0,B39))+C38 -> 56.5 | D39: =+YEAR(A39)*1000+MONTH(A39) -> 2014005 | F39: 42217 | G39: =SUMIF($D$20:$D$10011,J39,$B$20:$B$10011) -> 372.9 | H39: =IF(G39="nd",0, IF(G39="T",0,G39))+H38 -> 960.4 | I39: =+YEAR(F39) -> 2015 | J39: =+YEAR(F39)*1000+MONTH(F39) -> 2015008
A40: =+'Rainfall Data'!B39 -> 41779 | B40: =+'Rainfall Data'!C39 -> 12 | C40: =IF(B40="nd",0, IF(B40="T",0,B40))+C39 -> 68.5 | D40: =+YEAR(A40)*1000+MONTH(A40) -> 2014005 | F40: 42248 | G40: =SUMIF($D$20:$D$10011,J40,$B$20:$B$10011) -> 382.8 | H40: =IF(G40="nd",0, IF(G40="T",0,G40))+H39 -> 1343.2 | I40: =+YEAR(F40) -> 2015 | J40: =+YEAR(F40)*1000+MONTH(F40) -> 2015009
A41: =+'Rainfall Data'!B40 -> 41780 | B41: =+'Rainfall Data'!C40 -> 0 | C41: =IF(B41="nd",0, IF(B41="T",0,B41))+C40 -> 68.5 | D41: =+YEAR(A41)*1000+MONTH(A41) -> 2014005 | F41: 42278 | G41: =SUMIF($D$20:$D$10011,J41,$B$20:$B$10011) -> 397.4 | H41: =IF(G41="nd",0, IF(G41="T",0,G41))+H40 -> 1740.6 | I41: =+YEAR(F41) -> 2015 | J41: =+YEAR(F41)*1000+MONTH(F41) -> 2015010
...

Sheet Report Graphs
A1: =+'Rainfall Totals'!B1 & " " & 'Rainfall Totals'!B2 -> SN25 Fadugu Agricultural College
