Workbook

Sheet Rainfall Data
A1: Site Reference Number | B1: AD01
A2: Site Name | B2: ADDAX - Automatic Weather Station 1
A3: Latitude | B3: 8.6855
A4: Longitude | B4: -12.168041
A5: Elevation (mASL) | B5: 60 | C5: m above sea level (approximate)
A6: Type of Data | B6: Rainfall Data
A7: Origin | B7: Addax Biosciences Envrionmental Management Team, Sierra Leone
A8: Ownership | B8: Addax Biosciences
A9: Other Details | B9: Water Security Project, 2012 to 2015
A10: Web Site | B10: www.salonewatersecurity.com
A11: Start of Data Record | B11: =+MIN(A:A) -> 41312
A12: End of Data Record | B12: =+MAX(A:A) -> 41790
A13: Number of Data Records | B13: =+COUNT(A:A) -> 479
A14: Data Notes | B14: nd = no data
A15: Other Notes: | B15: This data looks erroneous - totals are very much lower than elsewhere in the area.
A17: Date of Measurement | B17: Official Record Date (Same Day) | C17: Daily Rainfall
C18: mm
A19: 41312 | B19: 41312 | C19: 0
A20: 41313 | B20: 41313 | C20: 0
A21: 41314 | B21: 41314 | C21: 0
A22: 41315 | B22: 41315 | C22: 0
A23: 41316 | B23: 41316 | C23: 0
A24: 41317 | B24: 41317 | C24: 0
A25: 41318 | B25: 41318 | C25: 0
A26: 41319 | B26: 41319 | C26: 0
A27: 41320 | B27: 41320 | C27: nd
A28: 41321 | B28: 41321 | C28: 0
A29: 41322 | B29: 41322 | C29: 0
A30: 41323 | B30: 41323 | C30: 0
A31: 41324 | B31: 41324 | C31: 0
A32: 41325 | B32: 41325 | C32: 0
A33: 41326 | B33: 41326 | C33: 0
A34: 41327 | B34: 41327 | C34: 0
A35: 41328 | B35: 41328 | C35: 0
A36: 41329 | B36: 41329 | C36: 0
A37: 41330 | B37: 41330 | C37: 0
A38: 41331 | B38: 41331 | C38: 0
A39: 41332 | B39: 41332 | C39: 0
... A192: 41485 | B192: 41485 | C192: 0
A193: 41486 | B193: 41486 | C193: nd
...

Sheet Rainfall Totals
A1: Site Reference Number | B1: =+'Rainfall Data'!B1 -> AD01
A2: Site Name | B2: =+'Rainfall Data'!B2 -> ADDAX - Automatic Weather Station 1
A3: Latitude | B3: =+'Rainfall Data'!B3 -> 8.6855
A4: Longitude | B4: =+'Rainfall Data'!B4 -> -12.168041
A5: Elevation (mASL) | B5: =+'Rainfall Data'!B5 -> 60 | C5: =+'Rainfall Data'!C5 -> m above sea level (approximate)
A6: Type of Data | B6: =+'Rainfall Data'!B6 -> Rainfall Data
A7: Origin | B7: =+'Rainfall Data'!B7 -> Addax Biosciences Envrionmental Management Team, Sierra Leone
A8: Ownership | B8: =+'Rainfall Data'!B8 -> Addax Biosciences
A9: Other Details | B9: =+'Rainfall Data'!B9 -> Water Security Project, 2012 to 2015
A10: Web Site | B10: =+'Rainfall Data'!B10 -> www.salonewatersecurity.com
A11: Start of Data Record | B11: =+MIN(A:A) -> 41312
A12: End of Data Record | B12: =+MAX(A:A) -> 41790
A13: Number of Data Records | B13: =+COUNT(A:A) -> 479
A14: Data Notes | B14: =+'Rainfall Data'!B14 -> nd = no data
A15: Other Notes: | B15: =+'Rainfall Data'!B15 -> This data looks erroneous - totals are very much lower than elsewhere in the area.
A17: Daily and Cumulative Rainfall (mm) | F17: Monthly Rainfall (mm) | L17: Annual Rainfall (mm)
A18: Official Record Date (Same Day) | B18: Daily Rainfall | C18: Cumulative Rainfall | D18: Year/Month | F18: Month | G18: Monthly Rainfall | H18: Cumulative | I18: Year | J18: Year/Month | L18: Year | M18: Annual Rainfall | N18: Notes
B19: mm | C19: mm | G19: mm | H19: mm | M19: mm
A20: =+'Rainfall Data'!B19 -> 41312 | B20: =+'Rainfall Data'!C19 -> 0 | C20: =IF(B20="nd",0, IF(B20="T",0,B20)) -> 0 | D20: =+YEAR(A20)*100+MONTH(A20) -> 201302 | F20: 41305 | I20: =+YEAR(F20) -> 2013 | J20: =+YEAR(F20)*100+MONTH(F20) -> 201301 | L20: 2013 | M20: =SUMIF($I$20:$I$111,L20,$G$20:$G$111) -> 937 | N20: February to December
A21: =+'Rainfall Data'!B20 -> 41313 | B21: =+'Rainfall Data'!C20 -> 0 | C21: =IF(B21="nd",0, IF(B21="T",0,B21))+C20 -> 0 | D21: =+YEAR(A21)*100+MONTH(A21) -> 201302 | F21: 41333 | G21: =SUMIF($D$20:$D$1011,$J21,$B$20:$B$347) -> 0 | H21: =IF(G21="nd",0, IF(G21="T",0,G21))+H20 -> 0 | I21: =+YEAR(F21) -> 2013 | J21: =+YEAR(F21)*100+MONTH(F21) -> 201302 | L21: 2014
A22: =+'Rainfall Data'!B21 -> 41314 | B22: =+'Rainfall Data'!C21 -> 0 | C22: =IF(B22="nd",0, IF(B22="T",0,B22))+C21 -> 0 | D22: =+YEAR(A22)*100+MONTH(A22) -> 201302 | F22: 41364 | G22: =SUMIF($D$20:$D$1011,$J22,$B$20:$B$347) -> 43.4 | H22: =IF(G22="nd",0, IF(G22="T",0,G22))+H21 -> 43.4 | I22: =+YEAR(F22) -> 2013 | J22: =+YEAR(F22)*100+MONTH(F22) -> 201303
A23: =+'Rainfall Data'!B22 -> 41315 | B23: =+'Rainfall Data'!C22 -> 0 | C23: =IF(B23="nd",0, IF(B23="T",0,B23))+C22 -> 0 | D23: =+YEAR(A23)*100+MONTH(A23) -> 201302 | F23: 41394 | G23: =SUMIF($D$20:$D$1011,$J23,$B$20:$B$347) -> 9.7 | H23: =IF(G23="nd",0, IF(G23="T",0,G23))+H22 -> 53.1 | I23: =+YEAR(F23) -> 2013 | J23: =+YEAR(F23)*100+MONTH(F23) -> 201304
A24: =+'Rainfall Data'!B23 -> 41316 | B24: =+'Rainfall Data'!C23 -> 0 | C24: =IF(B24="nd",0, IF(B24="T",0,B24))+C23 -> 0 | D24: =+YEAR(A24)*100+MONTH(A24) -> 201302 | F24: 41425 | G24: =SUMIF($D$20:$D$1011,$J24,$B$20:$B$347) -> 213.6 | H24: =IF(G24="nd",0, IF(G24="T",0,G24))+H23 -> 266.7 | I24: =+YEAR(F24) -> 2013 | J24: =+YEAR(F24)*100+MONTH(F24) -> 201305
A25: =+'Rainfall Data'!B24 -> 41317 | B25: =+'Rainfall Data'!C24 -> 0 | C25: =IF(B25="nd",0, IF(B25="T",0,B25))+C24 -> 0 | D25: =+YEAR(A25)*100+MONTH(A25) -> 201302 | F25: 41455 | G25: =SUMIF($D$20:$D$1011,$J25,$B$20:$B$347) -> 364 | H25: =IF(G25="nd",0, IF(G25="T",0,G25))+H24 -> 630.7 | I25: =+YEAR(F25) -> 2013 | J25: =+YEAR(F25)*100+MONTH(F25) -> 201306
A26: =+'Rainfall Data'!B25 -> 41318 | B26: =+'Rainfall Data'!C25 -> 0 | C26: =IF(B26="nd",0, IF(B26="T",0,B26))+C25 -> 0 | D26: =+YEAR(A26)*100+MONTH(A26) -> 201302 | F26: 41486 | G26: =SUMIF($D$20:$D$1011,$J26,$B$20:$B$347) -> 203.9 | H26: =IF(G26="nd",0, IF(G26="T",0,G26))+H25 -> 834.6 | I26: =+YEAR(F26) -> 2013 | J26: =+YEAR(F26)*100+MONTH(F26) -> 201307
A27: =+'Rainfall Data'!B26 -> 41319 | B27: =+'Rainfall Data'!C26 -> 0 | C27: =IF(B27="nd",0, IF(B27="T",0,B27))+C26 -> 0 | D27: =+YEAR(A27)*100+MONTH(A27) -> 201302 | F27: 41517 | G27: =SUMIF($D$20:$D$1011,$J27,$B$20:$B$347) -> 12.8 | H27: =IF(G27="nd",0, IF(G27="T",0,G27))+H26 -> 847.4 | I27: =+YEAR(F27) -> 2013 | J27: =+YEAR(F27)*100+MONTH(F27) -> 201308
A28: =+'Rainfall Data'!B27 -> 41320 | B28: =+'Rainfall Data'!C27 -> nd | C28: =IF(B28="nd",0, IF(B28="T",0,B28))+C27 -> 0 | D28: =+YEAR(A28)*100+MONTH(A28) -> 201302 | F28: 41547 | G28: =SUMIF($D$20:$D$1011,$J28,$B$20:$B$347) -> 61.9 | H28: =IF(G28="nd",0, IF(G28="T",0,G28))+H27 -> 909.3 | I28: =+YEAR(F28) -> 2013 | J28: =+YEAR(F28)*100+MONTH(F28) -> 201309
A29: =+'Rainfall Data'!B28 -> 41321 | B29: =+'Rainfall Data'!C28 -> 0 | C29: =IF(B29="nd",0, IF(B29="T",0,B29))+C28 -> 0 | D29: =+YEAR(A29)*100+MONTH(A29) -> 201302 | F29: 41578 | G29: =SUMIF($D$20:$D$1011,$J29,$B$20:$B$347) -> 20.2 | H29: =IF(G29="nd",0, IF(G29="T",0,G29))+H28 -> 929.5 | I29: =+YEAR(F29) -> 2013 | J29: =+YEAR(F29)*100+MONTH(F29) -> 201310
A30: =+'Rainfall Data'!B29 -> 41322 | B30: =+'Rainfall Data'!C29 -> 0 | C30: =IF(B30="nd",0, IF(B30="T",0,B30))+C29 -> 0 | D30: =+YEAR(A30)*100+MONTH(A30) -> 201302 | F30: 41608 | G30: =SUMIF($D$20:$D$1011,$J30,$B$20:$B$347) -> 7.5 | H30: =IF(G30="nd",0, IF(G30="T",0,G30))+H29 -> 937 | I30: =+YEAR(F30) -> 2013 | J30: =+YEAR(F30)*100+MONTH(F30) -> 201311
A31: =+'Rainfall Data'!B30 -> 41323 | B31: =+'Rainfall Data'!C30 -> 0 | C31: =IF(B31="nd",0, IF(B31="T",0,B31))+C30 -> 0 | D31: =+YEAR(A31)*100+MONTH(A31) -> 201302 | F31: 41639 | G31: =SUMIF($D$20:$D$1011,$J31,$B$20:$B$347) -> 0 | H31: =IF(G31="nd",0, IF(G31="T",0,G31))+H30 -> 937 | I31: =+YEAR(F31) -> 2013 | J31: =+YEAR(F31)*100+MONTH(F31) -> 201312
A32: =+'Rainfall Data'!B31 -> 41324 | B32: =+'Rainfall Data'!C31 -> 0 | C32: =IF(B32="nd",0, IF(B32="T",0,B32))+C31 -> 0 | D32: =+YEAR(A32)*100+MONTH(A32) -> 201302 | F32: 41670 | G32: =SUMIF($D$20:$D$1011,$J32,$B$20:$B$347) -> 0 | H32: =IF(G32="nd",0, IF(G32="T",0,G32)) -> 0 | I32: =+YEAR(F32) -> 2014 | J32: =+YEAR(F32)*100+MONTH(F32) -> 201401
A33: =+'Rainfall Data'!B32 -> 41325 | B33: =+'Rainfall Data'!C32 -> 0 | C33: =IF(B33="nd",0, IF(B33="T",0,B33))+C32 -> 0 | D33: =+YEAR(A33)*100+MONTH(A33) -> 201302 | F33: 41698 | G33: =SUMIF($D$20:$D$1011,$J33,$B$20:$B$347) -> 0 | H33: =IF(G33="nd",0, IF(G33="T",0,G33))+H32 -> 0 | I33: =+YEAR(F33) -> 2014 | J33: =+YEAR(F33)*100+MONTH(F33) -> 201402
A34: =+'Rainfall Data'!B33 -> 41326 | B34: =+'Rainfall Data'!C33 -> 0 | C34: =IF(B34="nd",0, IF(B34="T",0,B34))+C33 -> 0 | D34: =+YEAR(A34)*100+MONTH(A34) -> 201302 | F34: 41729 | G34: =SUMIF($D$20:$D$1011,$J34,$B$20:$B$347) -> 0.2 | H34: =IF(G34="nd",0, IF(G34="T",0,G34))+H33 -> 0.2 | I34: =+YEAR(F34) -> 2014 | J34: =+YEAR(F34)*100+MONTH(F34) -> 201403
A35: =+'Rainfall Data'!B34 -> 41327 | B35: =+'Rainfall Data'!C34 -> 0 | C35: =IF(B35="nd",0, IF(B35="T",0,B35))+C34 -> 0 | D35: =+YEAR(A35)*100+MONTH(A35) -> 201302 | F35: 41759 | G35: =SUMIF($D$20:$D$1011,$J35,$B$20:$B$347) -> 6.9 | H35: =IF(G35="nd",0, IF(G35="T",0,G35))+H34 -> 7.1 | I35: =+YEAR(F35) -> 2014 | J35: =+YEAR(F35)*100+MONTH(F35) -> 201404
A36: =+'Rainfall Data'!B35 -> 41328 | B36: =+'Rainfall Data'!C35 -> 0 | C36: =IF(B36="nd",0, IF(B36="T",0,B36))+C35 -> 0 | D36: =+YEAR(A36)*100+MONTH(A36) -> 201302 | F36: 41790 | G36: =SUMIF($D$20:$D$1011,$J36,$B$20:$B$347) -> 7 | H36: =IF(G36="nd",0, IF(G36="T",0,G36))+H35 -> 14.1 | I36: =+YEAR(F36) -> 2014 | J36: =+YEAR(F36)*100+MONTH(F36) -> 201405
A37: =+'Rainfall Data'!B36 -> 41329 | B37: =+'Rainfall Data'!C36 -> 0 | C37: =IF(B37="nd",0, IF(B37="T",0,B37))+C36 -> 0 | D37: =+YEAR(A37)*100+MONTH(A37) -> 201302
A38: =+'Rainfall Data'!B37 -> 41330 | B38: =+'Rainfall Data'!C37 -> 0 | C38: =IF(B38="nd",0, IF(B38="T",0,B38))+C37 -> 0 | D38: =+YEAR(A38)*100+MONTH(A38) -> 201302
A39: =+'Rainfall Data'!B38 -> 41331 | B39: =+'Rainfall Data'!C38 -> 0 | C39: =IF(B39="nd",0, IF(B39="T",0,B39))+C38 -> 0 | D39: =+YEAR(A39)*100+MONTH(A39) -> 201302
A40: =+'Rainfall Data'!B39 -> 41332 | B40: =+'Rainfall Data'!C39 -> 0 | C40: =IF(B40="nd",0, IF(B40="T",0,B40))+C39 -> 0 | D40: =+YEAR(A40)*100+MONTH(A40) -> 201302
A41: =+'Rainfall Data'!B40 -> 41333 | B41: =+'Rainfall Data'!C40 -> 0 | C41: =IF(B41="nd",0, IF(B41="T",0,B41))+C40 -> 0 | D41: =+YEAR(A41)*100+MONTH(A41) -> 201302
...

Sheet Graphs
A1: =+'Rainfall Totals'!B1 & " " & 'Rainfall Totals'!B2 -> AD01 ADDAX - Automatic Weather Station 1
